<?xml version="1.0"?>
<robot xmlns:xacro="http://www.ros.org/wiki/xacro">
     
    <xacro:macro name="fixed_joint" params="name parent child pos_z">
    <joint name="${name}" type="fixed">
        <parent link="${parent}"/>
        <child link="${child}"/>
        <origin rpy="0 0 0" xyz="0 0 ${pos_z}"/>
      </joint>
    </xacro:macro>
    
    
    <xacro:macro name="revolute_joint" params="name parent child axis pos_z">
    <joint name="${name}" type="revolute">
        <parent link="${parent}"/>
        <child link="${child}"/>
    
        <xacro:if value="${axis== 'x'}">
          <axis xyz="1 0 0"/>
        </xacro:if>
        <xacro:if value="${axis == 'y'}">
          <axis xyz="0 1 0"/>
        </xacro:if>
        <xacro:if value="${axis == 'z'}">
          <axis xyz="0 0 1"/>
        </xacro:if>
    
        <origin rpy="0 0 0" xyz="0 0 ${pos_z}"/>
        <limit effort="87" lower="-2.8973" upper="2.8973" velocity="2.1750"/>
    </joint>
    </xacro:macro>
    

</robot>